Workbook

Sheet Orçamento
A1: Data - Ano | C1: 2026 | D1: 2026 | E1: 2026 | F1: 2026 | G1: 2026 | H1: 2026 | I1: 2026 | J1: 2026 | K1: 2026 | L1: 2026 | M1: 2026 | N1: 2026 | O1: 2026 | P1: 2027 | Q1: 2027 | R1: 2027 | S1: 2027 | T1: Total
A2: Data - Nome do Mês | C2: janeiro | D2: fevereiro | E2: março | F2: abril | G2: maio | H2: junho | I2: julho | J2: agosto | K2: setembro | L2: outubro | M2: novembro | N2: dezembro | O2: Total | P2: janeiro | Q2: fevereiro | R2: março | S2: Total
A3: N4 | B3: NomeLB | C3: BG_Q2 | D3: BG_Q2 | E3: BG_Q2 | F3: BG_Q2 | G3: BG_Q2 | H3: BG_Q2 | I3: BG_Q2 | J3: BG_Q2 | K3: BG_Q2 | L3: BG_Q2 | M3: BG_Q2 | N3: BG_Q2 | O3: BG_Q2 | P3: BG_Q2 | Q3: BG_Q2 | R3: BG_Q2 | S3: BG_Q2 | T3: BG_Q2
A4: Plat. De Captação E Produção | B4: Total | C4: 5158292.3 | D4: 2654327.5 | E4: 2172937 | F4: 4016051.8 | G4: 2120877.7 | H4: 11178131 | I4: 3530361.4 | J4: 10340810 | K4: 23600874 | L4: 3393934 | M4: 14969643 | N4: 14869869 | O4: 98006109 | P4: 1440768 | Q4: 1696094 | R4: 90001716 | S4: 93138578 | T4: 1.9114469e+08
A5: Plat. De Captação E Produção | B5: Nova Sede Brasília | G5: 301888.48 | H5: 79203.99 | I5: 881519.01 | J5: 140451.97 | K5: 140451.97 | L5: 1185452 | M5: 935451.97 | N5: 1314903.9 | O5: 4979323.3 | R5: 21471046 | S5: 21471046 | T5: 26450369
A6: Plat. De Captação E Produção | B6: Plataforma de Controles BH | D6: 616.07 | E6: 27779.38 | F6: 1128436 | G6: 358880.53 | H6: 2637153.6 | I6: 181153.58 | J6: 181153.58 | K6: 11352656 | L6: 352655.58 | M6: 352655.58 | N6: 5037260.6 | O6: 21610400 | R6: 1752000 | S6: 1752000 | T6: 23362400
A7: Plat. De Captação E Produção | B7: Plataforma de Controles JB - Controle 3 | K7: 0 | N7: 0 | O7: 0 | P7: 137053 | Q7: 928000 | R7: 18614347 | S7: 19679400 | T7: 19679400
A8: Plat. De Captação E Produção | B8: Core IP JB - Fase 2 de 3 | E8: 0 | F8: 0 | G8: 0 | H8: 1090938 | I8: 407664 | J8: 407664 | K8: 1954664 | L8: 91190 | M8: 91190 | N8: 1591190 | O8: 5634500 | R8: 9491900 | S8: 9491900 | T8: 15126400
A9: Plat. De Captação E Produção | B9: Core IP BH | E9: 49894.98 | F9: 0 | G9: 0 | H9: 1055710.3 | I9: 121710.32 | J9: 4039242.3 | K9: 185642.32 | L9: 63932 | M9: 63932 | N9: 1900536 | O9: 7480600.2 | R9: 3585800 | S9: 3585800 | T9: 11066400
A10: Plat. De Captação E Produção | B10: Roadmap Estudio Rede 4k - Cameras SP | E10: 0 | F10: 74658.42 | G10: 74658.42 | H10: 74658.42 | I10: 0 | J10: 0 | K10: 74658.42 | L10: 74658.42 | M10: 2808708 | N10: 0 | O10: 3182000.1 | R10: 5639800 | S10: 5639800 | T10: 8821800.1
A11: Plat. De Captação E Produção | B11: Monitor Wall G5, Multiviewer CTL2 SP, COT CPP EG e Monitoração de Audio JB | C11: 63588.35 | D11: 294259.25 | E11: 386189.75 | F11: 86203.93 | G11: 55561.83 | H11: 97266 | J11: 273818 | O11: 1256887.1 | R11: 5472559.5 | S11: 5472559.5 | T11: 6729446.6
A12: Plat. De Captação E Produção | B12: Roadmap Estudio Rede 4k - Cameras RJ | E12: 362006.97 | F12: 0 | G12: 0 | H12: 0 | I12: 0 | J12: 0 | K12: 0 | L12: 0 | M12: 27000 | N12: 27000 | O12: 416006.97 | R12: 6195993 | S12: 6195993 | T12: 6612000
A13: Plat. De Captação E Produção | B13: Controles JB Obsolescência – Mixer Controle 3 JB | C13: 1927354 | D13: 184953.12 | E13: 271282.96 | F13: 799614.21 | G13: 230067 | H13: 0 | J13: 330000 | K13: 0 | N13: 987461 | O13: 4730732.3 | T13: 4730732.3
A14: Plat. De Captação E Produção | B14: Obs. Crítica Tripes EG | E14: 0 | F14: 0 | G14: 0 | H14: 0 | I14: 0 | J14: 191790 | K14: 191790 | L14: 0 | M14: 1747420 | N14: 0 | O14: 2131000 | R14: 2219000 | S14: 2219000 | T14: 4350000
A15: Plat. De Captação E Produção | B15: Roadmap Controles - Obsolescência Audio Mixer | C15: 0 | D15: 0 | H15: 500282 | J15: 1113000 | K15: 0 | M15: 2044000 | O15: 3657282 | T15: 3657282
A16: Plat. De Captação E Produção | B16: Gnews no estúdio A | C16: 514606.7 | D16: 20276.48 | E16: 14043.59 | F16: 28724.19 | G16: 9005 | H16: 1512271 | I16: 0 | J16: 1019835 | O16: 3118762 | T16: 3118762
A17: Plat. De Captação E Produção | B17: Obs. Crítica Câmeras PTZs | E17: 0 | F17: 0 | G17: 0 | H17: 0 | I17: 0 | J17: 0 | K17: 0 | L17: 91350 | M17: 1757350 | N17: 91350 | O17: 1940050 | R17: 1104950 | S17: 1104950 | T17: 3045000
A18: Plat. De Captação E Produção | B18: Core IP JB - Fase 1 (50% Parque JB) | C18: 983453.71 | D18: 863083.44 | E18: 104607.74 | F18: 42993.793 | G18: 91256.043 | H18: 39210.803 | J18: 52713 | K18: 0 | L18: 467025 | O18: 2644343.5 | T18: 2644343.5
A19: Plat. De Captação E Produção | B19: Câmeras de Externa - Obs. crítica G5 | C19: 6251 | D19: 106837.5 | E19: 36926.41 | F19: 74483.267 | G19: 33627.137 | H19: 2119531.5 | K19: 224620 | O19: 2602276.8 | T19: 2602276.8
A20: Plat. De Captação E Produção | B20: Obsolescência - Microfone Sem fio e Paineis de Comunicação | C20: 98388.85 | D20: 1585.36 | E20: 21661 | F20: 3766.4 | G20: 3506.51 | H20: 0 | J20: 1224188 | K20: 0 | M20: 993601 | O20: 2346697.1 | T20: 2346697.1
A21: Plat. De Captação E Produção | B21: Kit Light Jornalismo - JB + Restante SP (2027) | R21: 2215600 | S21: 2215600 | T21: 2215600
A22: Plat. De Captação E Produção | B22: Kit Light Jornalismo - SP | E22: 103.83 | F22: 0 | G22: 0 | H22: 0 | I22: 99702 | J22: 99702 | K22: 1816688 | L22: 99702 | M22: 99702 | N22: 0 | O22: 2215599.8 | T22: 2215599.8
A23: Plat. De Captação E Produção | B23: Obs. Crítica Câmeras Super Slow | E23: 0 | F23: 0 | G23: 0 | H23: 0 | I23: 0 | J23: 84303 | K23: 84303 | L23: 0 | M23: 0 | N23: 0 | O23: 168606 | Q23: 768094 | R23: 936700 | S23: 1704794 | T23: 1873400
A24: Plat. De Captação E Produção | B24: Inovação em C&P | C24: 91879.63 | D24: 48453.75 | E24: 1718.28 | N24: 1559792.2 | O24: 1701843.8 | T24: 1701843.8
A25: Plat. De Captação E Produção | B25: Plataforma de Controles SP - Obs. Controle 1 SP_1 | C25: 383845.08 | D25: 231044.39 | E25: 42708.23 | F25: 738806.49 | G25: 68490.964 | H25: 38185.994 | I25: 74333.994 | J25: 38185.994 | O25: 1615601.1 | T25: 1615601.1
A26: Plat. De Captação E Produção | B26: Obsolescencia - Mixer Fantastico | E26: 0 | F26: 0 | G26: 0 | H26: 0 | I26: 0 | J26: 0 | K26: 0 | L26: 0 | M26: 6950 | N26: 96050.5 | O26: 103000.5 | P26: 89100 | R26: 1190954 | S26: 1280054 | T26: 1383054.5
A27: Plat. De Captação E Produção | B27: Escritório Londres | K27: 846896 | L27: 423104 | O27: 1270000 | T27: 1270000
A28: Plat. De Captação E Produção | B28: Comunicação Operacional - Obs. crítica BH, BSA e REC | C28: 5081.38 | D28: 0 | E28: 0 | F28: 24480 | G28: 552908.56 | H28: 0 | J28: 375611 | K28: 0 | M28: 194982 | O28: 1153062.9 | T28: 1153062.9
A29: Plat. De Captação E Produção | B29: Obs. Crítica Dramaturgia EG - Mattebox | C29: 0 | E29: 0 | F29: 0 | G29: 0 | H29: 0 | I29: 33234 | J29: 33234 | K29: 487432 | L29: 0 | M29: 0 | N29: 0 | O29: 553900 | R29: 553900 | S29: 553900 | T29: 1107800
A30: Plat. De Captação E Produção | B30: Obs. Crítica Dramaturgia EG - Monitores UPP (TV Logic) | C30: 0 | E30: 0 | F30: 0 | G30: 0 | H30: 0 | I30: 0 | J30: 0 | K30: 504049 | L30: 49851 | M30: 0 | N30: 0 | O30: 553900 | R30: 553900 | S30: 553900 | T30: 1107800
A31: Plat. De Captação E Produção | B31: Obs. Crítica Dramaturgia EG - Sistema de Mobilidade (Teradek) | C31: 0 | E31: 0 | F31: 0 | G31: 0 | H31: 99702 | I31: 99702 | J31: 0 | K31: 0 | L31: 0 | M31: 908396 | N31: 0 | O31: 1107800 | T31: 1107800
A32: Plat. De Captação E Produção | B32: Obs. Crítica Estúdios JB - Retrofit Grua Est-D | E32: 0 | F32: 0 | G32: 0 | H32: 0 | I32: 0 | J32: 0 | K32: 0 | L32: 0 | M32: 464464 | N32: 45936 | O32: 510400 | R32: 510400 | S32: 510400 | T32: 1020800
A33: Plat. De Captação E Produção | B33: Automação Hoists MG2 - Obs. Crítica e Mesa de Iluminação EST-3 SP | C33: 182152.75 | D33: 330891.32 | E33: 184398.32 | F33: 193080 | G33: 24625.43 | H33: 74773 | I33: 13999.4 | J33: 13999.4 | O33: 1017919.6 | T33: 1017919.6
A34: Plat. De Captação E Produção | B34: BC DSLR para UPs 2026 | E34: 0 | F34: 0 | G34: 0 | H34: 0 | I34: 0 | J34: 0 | K34: 800000 | L34: 91350 | M34: 123650 | N34: 0 | O34: 1015000 | T34: 1015000
A35: Plat. De Captação E Produção | B35: Roadmap de Câmeras - Dramaturgia - Fase 3 | C35: 0 | D35: 0 | E35: 0 | F35: 14119 | G35: 0 | M35: 0 | O35: 14119 | P35: 956787 | S35: 956787 | T35: 970906
A36: Plat. De Captação E Produção | B36: CEE - Câmera Estúdio Externa EG | C36: 0 | D36: 0 | E36: 0 | F36: 26705.01 | G36: 9356.32 | H36: 9356.32 | I36: 0 | K36: 700000 | M36: 206987 | O36: 952404.65 | T36: 952404.65
A37: Plat. De Captação E Produção | B37: Obs Comunicação Operacional - BH | E37: 0 | F37: 0 | G37: 0 | H37: 121959.66 | I37: 0 | J37: 0 | K37: 239508.04 | L37: 0 | M37: 60514.5 | N37: 93700.803 | O37: 515683 | R37: 355683 | S37: 355683 | T37: 871366
A38: Plat. De Captação E Produção | B38: Obs. Crítica Robôs ION | E38: 0 | F38: 0 | G38: 0 | H38: 0 | I38: 78300 | J38: 78300 | K38: 0 | L38: 0 | M38: 0 | N38: 713400 | O38: 870000 | T38: 870000
A39: Plat. De Captação E Produção | B39: Aquisição Kit diretor pro Entretenimento | E39: 0 | F39: 0 | G39: 38295 | H39: 38295 | I39: 0 | J39: 0 | K39: 593000 | L39: 0 | M39: 104820 | N39: 76590 | O39: 851000 | T39: 851000
A40: Plat. De Captação E Produção | B40: Roadmap de Câmeras - DSLR | D40: 17158.3 | E40: 0 | F40: 0 | G40: 0 | H40: 4884 | O40: 22042.3 | P40: 0 | R40: 814835.81 | S40: 814835.81 | T40: 836878.11
...

Sheet Realizado
A1: Data - Ano | B1: N4 | C1: 1º Aprovador | D1: NomeLB | E1: Orcamento | F1: Realizado | G1: Em Pgto | H1: Delta Caixa | I1: Compromisso | J1: A emitir
A2: 2027 | B2: Total | E2: 1.0677704e+08 | H2: 1.0677704e+08 | I2: 46652308 | J2: 60124728
A3: 2027 | B3: Plat. De Captação E Produção | C3: Total | E3: 93138578 | H3: 93138578 | I3: 38284055 | J3: 54854523
A4: 2027 | B4: Plat. De Captação E Produção | C4: tiago.faria@g.globo | D4: Total | E4: 21471046 | H4: 21471046 | I4: 1470088.9 | J4: 20000957
A5: 2027 | B5: Plat. De Captação E Produção | C5: tiago.faria@g.globo | D5: Nova Sede Brasília | E5: 21471046 | H5: 21471046 | I5: 1470088.9 | J5: 20000957
A6: 2027 | B6: Plat. De Captação E Produção | C6: tiago.faria@g.globo | D6: Adequações de produção 4k | I6: 0 | J6: 0
A7: 2027 | B7: Plat. De Captação E Produção | C7: diogo.silva@g.globo | D7: Total | E7: 19679400 | H7: 19679400 | I7: 287934.52 | J7: 19391466
A8: 2027 | B8: Plat. De Captação E Produção | C8: diogo.silva@g.globo | D8: Plataforma de Controles JB - Controle 3 | E8: 19679400 | H8: 19679400 | I8: 272891.55 | J8: 19406509
A9: 2027 | B9: Plat. De Captação E Produção | C9: diogo.silva@g.globo | D9: Plataforma de Controles RJ - Obs. Controle 3 ION | E9: 0 | H9: 0 | I9: 15042.97 | J9: -15042.97
A10: 2027 | B10: Plat. De Captação E Produção | C10: diogo.silva@g.globo | D10: Solução All In One | E10: 0 | H10: 0 | J10: 0
A11: 2027 | B11: Plat. De Captação E Produção | C11: rodrigo.ogura@g.globo | D11: Total | E11: 18550259 | H11: 18550259 | I11: 11969605 | J11: 6580654
A12: 2027 | B12: Plat. De Captação E Produção | C12: rodrigo.ogura@g.globo | D12: Core IP JB - Fase 2 de 3 | E12: 9491900 | H12: 9491900 | I12: 3880437.5 | J12: 5611462.5
A13: 2027 | B13: Plat. De Captação E Produção | C13: rodrigo.ogura@g.globo | D13: Monitor Wall G5, Multiviewer CTL2 SP, COT CPP EG e Monitoração de Audio JB | E13: 5472559.5 | H13: 5472559.5 | I13: 216305.8 | J13: 5256253.7
A14: 2027 | B14: Plat. De Captação E Produção | C14: rodrigo.ogura@g.globo | D14: Core IP BH | E14: 3585800 | H14: 3585800 | I14: 7269611.5 | J14: -3683811.5
A15: 2027 | B15: Plat. De Captação E Produção | C15: rodrigo.ogura@g.globo | D15: Core IP JB - Fase 1 (50% Parque JB) | E15: 0 | H15: 0 | I15: 482868.61 | J15: -482868.61
A16: 2027 | B16: Plat. De Captação E Produção | C16: rodrigo.ogura@g.globo | D16: Georreferenciamento para o site ÍON | E16: 0 | H16: 0 | I16: 0 | J16: 0
A17: 2027 | B17: Plat. De Captação E Produção | C17: rodrigo.ogura@g.globo | D17: Georreferenciamento SP | E17: 0 | H17: 0 | I17: 0 | J17: 0
A18: 2027 | B18: Plat. De Captação E Produção | C18: rodrigo.ogura@g.globo | D18: Operação Remota BSA x JB | E18: 0 | H18: 0 | I18: 10539.51 | J18: -10539.51
A19: 2027 | B19: Plat. De Captação E Produção | C19: rodrigo.ogura@g.globo | D19: Pool Recursos Controles de Eventos | E19: 0 | H19: 0 | I19: 4354.97 | J19: -4354.97
A20: 2027 | B20: Plat. De Captação E Produção | C20: rodrigo.ogura@g.globo | D20: Roadmap Controles - Obsolescência Multiviewer | E20: 0 | H20: 0 | I20: 105487.58 | J20: -105487.58
A21: 2027 | B21: Plat. De Captação E Produção | C21: arthurnsantos@g.globo | D21: Total | E21: 12938481 | H21: 12938481 | I21: 4703588.2 | J21: 8234892.8
A22: 2027 | B22: Plat. De Captação E Produção | C22: arthurnsantos@g.globo | D22: Roadmap Estudio Rede 4k - Cameras SP | E22: 5639800 | H22: 5639800 | I22: 183569.53 | J22: 5456230.5
A23: 2027 | B23: Plat. De Captação E Produção | C23: arthurnsantos@g.globo | D23: Kit Light Jornalismo - JB + Restante SP (2027) | E23: 2215600 | H23: 2215600 | J23: 2215600
A24: 2027 | B24: Plat. De Captação E Produção | C24: arthurnsantos@g.globo | D24: Obs. Crítica Câmeras Super Slow | E24: 1704794 | H24: 1704794 | I24: 140796 | J24: 1563998
A25: 2027 | B25: Plat. De Captação E Produção | C25: arthurnsantos@g.globo | D25: Roadmap de Câmeras - Dramaturgia - Fase 3 | E25: 956787 | H25: 956787 | J25: 956787
A26: 2027 | B26: Plat. De Captação E Produção | C26: arthurnsantos@g.globo | D26: Obs. Crítica Canhões Seguidores MG2 (2027) | E26: 524900 | H26: 524900 | J26: 524900
A27: 2027 | B27: Plat. De Captação E Produção | C27: arthurnsantos@g.globo | D27: Iluminação SP - Estúdio/Controle 3 | E27: 501700 | H27: 501700 | J27: 501700
A28: 2027 | B28: Plat. De Captação E Produção | C28: arthurnsantos@g.globo | D28: Iluminação SP - Mesa Estúdio 1 | E28: 501700 | H28: 501700 | J28: 501700
A29: 2027 | B29: Plat. De Captação E Produção | C29: arthurnsantos@g.globo | D29: Iluminação SP - Mesa Glass SP | E29: 501700 | H29: 501700 | J29: 501700
A30: 2027 | B30: Plat. De Captação E Produção | C30: arthurnsantos@g.globo | D30: Obs. Crítica Câmeras Ion - CAMBOX Estúdio C | E30: 391500 | H30: 391500 | J30: 391500
A31: 2027 | B31: Plat. De Captação E Produção | C31: arthurnsantos@g.globo | D31: Automação Hoists MG2 - Obs. Crítica e Mesa de Iluminação EST-3 SP | E31: 0 | H31: 0 | I31: 75879.25 | J31: -75879.25
A32: 2027 | B32: Plat. De Captação E Produção | C32: arthurnsantos@g.globo | D32: BC Iluminação Branca Estúdio 1 SP | E32: 0 | H32: 0 | I32: 187153.48 | J32: -187153.48
A33: 2027 | B33: Plat. De Captação E Produção | C33: arthurnsantos@g.globo | D33: Câmeras de Externa - Obs. crítica G5 | E33: 0 | H33: 0 | I33: 314761.72 | J33: -314761.72
A34: 2027 | B34: Plat. De Captação E Produção | C34: arthurnsantos@g.globo | D34: Câmeras Robô - Obs. crítica ION | E34: 0 | H34: 0 | I34: 17049.88 | J34: -17049.88
A35: 2027 | B35: Plat. De Captação E Produção | C35: arthurnsantos@g.globo | D35: Câmeras Robóticas G5 | E35: 0 | H35: 0 | I35: 558.15 | J35: -558.15
A36: 2027 | B36: Plat. De Captação E Produção | C36: arthurnsantos@g.globo | D36: CEE - Câmera Estúdio Externa EG | E36: 0 | H36: 0 | I36: 277353.26 | J36: -277353.26
A37: 2027 | B37: Plat. De Captação E Produção | C37: arthurnsantos@g.globo | D37: Gnews no estúdio A | E37: 0 | H37: 0 | I37: 39583.43 | J37: -39583.43
A38: 2027 | B38: Plat. De Captação E Produção | C38: arthurnsantos@g.globo | D38: Iluminação SP - Mesa e acessórios JG e JH | E38: 0 | H38: 0 | I38: 107878.98 | J38: -107878.98
A39: 2027 | B39: Plat. De Captação E Produção | C39: arthurnsantos@g.globo | D39: Kit de Externa Internacional | E39: 0 | H39: 0 | J39: 0
A40: 2027 | B40: Plat. De Captação E Produção | C40: arthurnsantos@g.globo | D40: Kit Light Jornalismo - SP | E40: 0 | H40: 0 | I40: 1786533.6 | J40: -1786533.6
...

Sheet Hierarquia
A1: N3 | B1: N4 | C1: nome gestor | D1: email gestor
A2: Plataformas de Produção | B2: Plat. De Captação E Produção | C2: Marcelo Fontana | D2: marcelo.fontana@g.globo
A3: Plataformas de Produção | B3: Plat. De Pós-Prod. E Design | C3: Wagner Telles | D3: wagner.telles@g.globo
A4: Plataformas de Produção | B4: Plat. De Metadados E Mídias | C4: Adonias Melo | D4: adonias.melo@g.globo
A5: Plataformas de Produção | B5: Plataforma De Pré-Produção | C5: Leonardo Cabral | D5: leonardo.cabral@g.globo

Sheet Status Report
A1: 📊 STATUS REPORT - FLUXO DE CAIXA 2026 | Plataformas de Produção
A2: Data Base: 27/07/2026 | Preparado para: Reunião com Diretor N3
A4: RESUMO EXECUTIVO POR PLATAFORMA (N4) - VISÃO PLURIANUAL
A5: Plataforma (N4) | B5: Gestor | C5: Orç. Plurianual | D5: Orç. 2026 | E5: Realizado + Em pgt 2026 | F5: % Exec 2026 | G5: Compromisso | H5: Provisionado | I5: % Orç. Plurianual | J5: A Emitir | K5: Status
A6: Plat. De Captação E Produção | B6: Marcelo Fontana | C6: =Orçamento!T4 -> 1.9114469e+08 | D6: =Realizado!E241 -> 97999337 | E6: =Realizado!F241+Realizado!G241 -> 34962378 | F6: =IF(D6=0,0,E6/D6) -> 0.35676137 | G6: =Realizado!I241 -> 38284055 | H6: =E6+G6 -> 73246433 | I6: =IF(C6=0,0,H6/C6) -> 0.3831989 | J6: =C6-H6 -> 1.1789825e+08 | K6: =IF(I6>1,"🔴 ESTOURO",IF(I6<0.3,"🟠 BAIXO COMPROM.",IF(F6<0.4,"🟡 BAIXA EXEC","🟢 OK"))) -> 🟡 BAIXA EXEC
A7: Plat. De Pós-Prod. E Design | B7: Wagner Telles | C7: =Orçamento!T114 -> 49757090 | D7: =Realizado!E381 -> 39906689 | E7: =Realizado!F381+Realizado!G381 -> 15031739 | F7: =IF(D7=0,0,E7/D7) -> 0.37667217 | G7: =Realizado!I381 -> 5815690.2 | H7: =E7+G7 -> 20847429 | I7: =IF(C7=0,0,H7/C7) -> 0.4189841 | J7: =C7-H7 -> 28909660 | K7: =IF(I7>1,"🔴 ESTOURO",IF(I7<0.3,"🟠 BAIXO COMPROM.",IF(F7<0.4,"🟡 BAIXA EXEC","🟢 OK"))) -> 🟡 BAIXA EXEC
A8: Plat. De Metadados E Mídias | B8: Adonias Melo | C8: =Orçamento!T173 -> 10736712 | D8: =Realizado!E452 -> 6944833.7 | E8: =Realizado!F452+Realizado!G452 -> 3753663.4 | F8: =IF(D8=0,0,E8/D8) -> 0.54049723 | G8: =Realizado!I452 -> 2552562.6 | H8: =E8+G8 -> 6306226 | I8: =IF(C8=0,0,H8/C8) -> 0.58735168 | J8: =C8-H8 -> 4430486.3 | K8: =IF(I8>1,"🔴 ESTOURO",IF(I8<0.3,"🟠 BAIXO COMPROM.",IF(F8<0.4,"🟡 BAIXA EXEC","🟢 OK"))) -> 🟢 OK
A9: Plataforma De Pré-Produção | B9: Leonardo Cabral | C9: =Orçamento!T186 -> 124135.83 | D9: =Orçamento!O186 -> 124135.83 | E9: 0 | F9: =IF(D9=0,0,E9/D9) -> 0 | G9: 0 | H9: =E9+G9 -> 0 | I9: =IF(C9=0,0,H9/C9) -> 0 | J9: =C9-H9 -> 124135.83 | K9: =IF(I9>1,"🔴 ESTOURO",IF(I9<0.3,"🟠 BAIXO COMPROM.",IF(F9<0.4,"🟡 BAIXA EXEC","🟢 OK"))) -> 🟠 BAIXO COMPROM.
A10: TOTAL GERAL | B10: - | C10: =SUM(C6:C9) -> 2.5176262e+08 | D10: =SUM(D6:D9) -> 1.44975e+08 | E10: =SUM(E6:E9) -> 53747780 | F10: =IF(D10=0,0,E10/D10) -> 0.37073828 | G10: =SUM(G6:G9) -> 46652308 | H10: =SUM(H6:H9) -> 1.0040009e+08 | I10: =IF(C10=0,0,H10/C10) -> 0.39878869 | J10: =SUM(J6:J9) -> 1.5136254e+08 | K10: =IF(I10>1,"🔴 ESTOURO",IF(I10<0.3,"🟠 BAIXO COMPROM.",IF(F10<0.4,"🟡 BAIXA EXEC","🟢 OK"))) -> 🟡 BAIXA EXEC
A12: 📊 ANÁLISE DE RISCO - VISÃO CORRIGIDA
A13: Total de Projetos Analisados: | B13: 205
A14: 🟠 BAIXO COMPROMISSO (< 80% do Caixa 2026, excl. Pré-Prod) - FOCO: | B14: 91
A15: 🔴 ESTOURO DE ORÇAMENTO PLURIANUAL (Comprom. > Orç. Total): | B15: 39
A16: 💰 Valor Total A EMITIR (projetos baixo compromisso): | B16: =SUMIF(I21:I35,">0",I21:I35) -> 0
A18: ⚠️ FOCO: PROJETOS COM BAIXO COMPROMISSO vs CAIXA 2026
A19: # | B19: Projeto (NomeLB) | C19: Plataforma (N4) | D19: Orç. Caixa 2026 | E19: Compromisso | F19: % Comprom. | G19: Falta Comprometer | H19: Executado | I19: Prioridade
A20: 1 | B20: =Realizado!D243 -> Plataforma de Controles BH | C20: =Realizado!B243 -> Plat. De Captação E Produção | D20: =Realizado!E243 -> 21610400 | E20: =Realizado!I243 -> 7869727.3 | F20: =IF(D20=0,0,E20/D20) -> 0.36416389 | G20: =D20-E20 -> 13740673 | H20: =Realizado!F243+Realizado!G243 -> 4517939.8 | I20: =IF(G20>5000000,"🔥 CRÍTICO",IF(G20>2000000,"⚠️ ALTO",IF(G20>1000000,"📋 MÉDIO","📌 BAIXO"))) -> 🔥 CRÍTICO
A21: 2 | B21: =Realizado!D383 -> Ilhas de Edição (42) | C21: =Realizado!B383 -> Plat. De Pós-Prod. E Design | D21: =Realizado!E383 -> 6353445.6 | E21: =Realizado!I383 -> 119370.75 | F21: =IF(D21=0,0,E21/D21) -> 0.018788349 | G21: =D21-E21 -> 6234074.8 | H21: =Realizado!F383+Realizado!G383 -> 3781210.3 | I21: =IF(G21>5000000,"🔥 CRÍTICO",IF(G21>2000000,"⚠️ ALTO",IF(G21>1000000,"📋 MÉDIO","📌 BAIXO"))) -> 🔥 CRÍTICO
A22: 3 | B22: =Realizado!D331 -> Controles JB Obsolescência – Mixer Controle 3 JB | C22: =Realizado!B331 -> Plat. De Captação E Produção | D22: =Realizado!E331 -> 4730732.3 | E22: =Realizado!I331 -> 317572.35 | F22: =IF(D22=0,0,E22/D22) -> 0.067129639 | G22: =D22-E22 -> 4413159.9 | H22: =Realizado!F331+Realizado!G331 -> 3705127.8 | I22: =IF(G22>5000000,"🔥 CRÍTICO",IF(G22>2000000,"⚠️ ALTO",IF(G22>1000000,"📋 MÉDIO","📌 BAIXO"))) -> ⚠️ ALTO
A23: 4 | B23: =Realizado!D362 -> Nova Sede Brasília | C23: =Realizado!B362 -> Plat. De Captação E Produção | D23: =Realizado!E362 -> 4979323.3 | E23: =Realizado!I362 -> 1470088.9 | F23: =IF(D23=0,0,E23/D23) -> 0.2952387 | G23: =D23-E23 -> 3509234.3 | H23: =Realizado!F362+Realizado!G362 -> 270549.3 | I23: =IF(G23>5000000,"🔥 CRÍTICO",IF(G23>2000000,"⚠️ ALTO",IF(G23>1000000,"📋 MÉDIO","📌 BAIXO"))) -> ⚠️ ALTO
A24: 5 | B24: =Realizado!D292 -> Roadmap Estudio Rede 4k - Cameras SP | C24: =Realizado!B292 -> Plat. De Captação E Produção | D24: =Realizado!E292 -> 3182000.1 | E24: =Realizado!I292 -> 183569.53 | F24: =IF(D24=0,0,E24/D24) -> 0.057689982 | G24: =D24-E24 -> 2998430.6 | H24: =Realizado!F292+Realizado!G292 -> 189722.47 | I24: =IF(G24>5000000,"🔥 CRÍTICO",IF(G24>2000000,"⚠️ ALTO",IF(G24>1000000,"📋 MÉDIO","📌 BAIXO"))) -> ⚠️ ALTO
A25: 6 | B25: =Realizado!D329 -> Roadmap Controles - Obsolescência Audio Mixer | C25: =Realizado!B329 -> Plat. De Captação E Produção | D25: =Realizado!E329 -> 3657282 | E25: =Realizado!I329 -> 803166.05 | F25: =IF(D25=0,0,E25/D25) -> 0.21960736 | G25: =D25-E25 -> 2854116 | H25: =Realizado!F329+Realizado!G329 -> 130880.12 | I25: =IF(G25>5000000,"🔥 CRÍTICO",IF(G25>2000000,"⚠️ ALTO",IF(G25>1000000,"📋 MÉDIO","📌 BAIXO"))) -> ⚠️ ALTO
A26: 7 | B26: =Realizado!D438 -> Roadmap Playout Controles - SP/JB/BSA | C26: =Realizado!B438 -> Plat. De Pós-Prod. E Design | D26: =Realizado!E438 -> 2485258.9 | E26: =Realizado!I438 -> 111520.18 | F26: =IF(D26=0,0,E26/D26) -> 0.044872661 | G26: =D26-E26 -> 2373738.7 | H26: =Realizado!F438+Realizado!G438 -> 225503.58 | I26: =IF(G26>5000000,"🔥 CRÍTICO",IF(G26>2000000,"⚠️ ALTO",IF(G26>1000000,"📋 MÉDIO","📌 BAIXO"))) -> ⚠️ ALTO
A27: 8 | B27: =Realizado!D402 -> Estações Design (33) - EG | C27: =Realizado!B402 -> Plat. De Pós-Prod. E Design | D27: =Realizado!E402 -> 2704697.1 | E27: =Realizado!I402 -> 333256.19 | F27: =IF(D27=0,0,E27/D27) -> 0.12321387 | G27: =D27-E27 -> 2371441 | H27: =Realizado!F402+Realizado!G402 -> 385798.81 | I27: =IF(G27>5000000,"🔥 CRÍTICO",IF(G27>2000000,"⚠️ ALTO",IF(G27>1000000,"📋 MÉDIO","📌 BAIXO"))) -> ⚠️ ALTO
A28: 9 | B28: =Realizado!D301 -> Câmeras de Externa - Obs. crítica G5 | C28: =Realizado!B301 -> Plat. De Captação E Produção | D28: =Realizado!E301 -> 2602276.8 | E28: =Realizado!I301 -> 314761.72 | F28: =IF(D28=0,0,E28/D28) -> 0.12095628 | G28: =D28-E28 -> 2287515.1 | H28: =Realizado!F301+Realizado!G301 -> 2229287.9 | I28: =IF(G28>5000000,"🔥 CRÍTICO",IF(G28>2000000,"⚠️ ALTO",IF(G28>1000000,"📋 MÉDIO","📌 BAIXO"))) -> ⚠️ ALTO
A29: 10 | B29: =Realizado!D417 -> Workflow 4K de edição | C29: =Realizado!B417 -> Plat. De Pós-Prod. E Design | D29: =Realizado!E417 -> 2472312.7 | E29: =Realizado!I417 -> 231676.11 | F29: =IF(D29=0,0,E29/D29) -> 0.093708255 | G29: =D29-E29 -> 2240636.6 | H29: =Realizado!F417+Realizado!G417 -> 625032.49 | I29: =IF(G29>5000000,"🔥 CRÍTICO",IF(G29>2000000,"⚠️ ALTO",IF(G29>1000000,"📋 MÉDIO","📌 BAIXO"))) -> ⚠️ ALTO
A30: 11 | B30: =Realizado!D403 -> Renders VFX (35) | C30: =Realizado!B403 -> Plat. De Pós-Prod. E Design | D30: =Realizado!E403 -> 1892440.1 | E30: =Realizado!I403 -> 20783.52 | F30: =IF(D30=0,0,E30/D30) -> 0.010982392 | G30: =D30-E30 -> 1871656.6 | H30: =Realizado!F403+Realizado!G403 -> 316581.24 | I30: =IF(G30>5000000,"🔥 CRÍTICO",IF(G30>2000000,"⚠️ ALTO",IF(G30>1000000,"📋 MÉDIO","📌 BAIXO"))) -> 📋 MÉDIO
A31: 12 | B31: =Realizado!D353 -> Core IP JB - Fase 2 de 3 | C31: =Realizado!B353 -> Plat. De Captação E Produção | D31: =Realizado!E353 -> 5634500 | E31: =Realizado!I353 -> 3880437.5 | F31: =IF(D31=0,0,E31/D31) -> 0.68869243 | G31: =D31-E31 -> 1754062.5 | H31: =Realizado!F353+Realizado!G353 -> 1675091.9 | I31: =IF(G31>5000000,"🔥 CRÍTICO",IF(G31>2000000,"⚠️ ALTO",IF(G31>1000000,"📋 MÉDIO","📌 BAIXO"))) -> 📋 MÉDIO
A32: 13 | B32: =Realizado!D268 -> Inovação em C&P | C32: =Realizado!B268 -> Plat. De Captação E Produção | D32: =Realizado!E268 -> 1701843.8 | E32: =Realizado!I268 -> 21684.14 | F32: =IF(D32=0,0,E32/D32) -> 0.012741557 | G32: =D32-E32 -> 1680159.7 | H32: =Realizado!F268+Realizado!G268 -> 178653.48 | I32: =IF(G32>5000000,"🔥 CRÍTICO",IF(G32>2000000,"⚠️ ALTO",IF(G32>1000000,"📋 MÉDIO","📌 BAIXO"))) -> 📋 MÉDIO
A33: 14 | B33: =Realizado!D418 -> Obs. Ingest Live Ion - Fase 2 | C33: =Realizado!B418 -> Plat. De Pós-Prod. E Design | D33: =Realizado!E418 -> 1663397.6 | E33: =Realizado!I418 -> 18531.08 | F33: =IF(D33=0,0,E33/D33) -> 0.011140499 | G33: =D33-E33 -> 1644866.5 | H33: =Realizado!F418+Realizado!G418 -> 1338282.4 | I33: =IF(G33>5000000,"🔥 CRÍTICO",IF(G33>2000000,"⚠️ ALTO",IF(G33>1000000,"📋 MÉDIO","📌 BAIXO"))) -> 📋 MÉDIO
A34: 15 | B34: =Realizado!D330 -> Obsolescência - Microfone Sem fio e Paineis de Comunicação | C34: =Realizado!B330 -> Plat. De Captação E Produção | D34: =Realizado!E330 -> 2346697.1 | E34: =Realizado!I330 -> 748465.34 | F34: =IF(D34=0,0,E34/D34) -> 0.31894416 | G34: =D34-E34 -> 1598231.8 | H34: =Realizado!F330+Realizado!G330 -> 190601.95 | I34: =IF(G34>5000000,"🔥 CRÍTICO",IF(G34>2000000,"⚠️ ALTO",IF(G34>1000000,"📋 MÉDIO","📌 BAIXO"))) -> 📋 MÉDIO
A35: 📊 Critérios: Compromisso < 80% do Caixa 2026 | A Comprometer > R$ 50k | Excluindo Pré-Produção
A36: 🔴 ESTOURO REAL DE ORÇAMENTO PLURIANUAL (Comprometido > Orçamento Total)
A37: Nota: Estes projetos TÊM compromisso superior ao orçamento plurianual aprovado - requer ação corretiva.
A38: # | B38: Projeto (NomeLB) | C38: Plataforma (N4) | D38: Orç. Plurianual | E38: Executado | F38: Compromisso | G38: % do Orç. | H38: Desvio R$ | I38: Ação
A39: 1 | B39: =Realizado!D359 -> Core IP JB - Fase 1 (50% Parque JB) | C39: =Realizado!B359 -> Plat. De Captação E Produção | D39: =IFERROR(VLOOKUP(B39,Orçamento!B:T,19,FALSE),Realizado!E359) -> 2644343.5 | E39: =Realizado!F359+Realizado!G359 -> 2756364.8 | F39: =Realizado!I359 -> 482868.61 | G39: =IF(D39=0,0,(E39+F39)/D39) -> 1.2249669 | H39: =(E39+F39)-D39 -> 594889.84 | I39: Revisar compromisso
A40: 2 | B40: =Realizado!D264 -> Plataforma de Controles SP - Obs. Controle 1 SP_1 | C40: =Realizado!B264 -> Plat. De Captação E Produção | D40: =IFERROR(VLOOKUP(B40,Orçamento!B:T,19,FALSE),Realizado!E264) -> 1615601.1 | E40: =Realizado!F264+Realizado!G264 -> 1849744.3 | F40: =Realizado!I264 -> 163091.55 | G40: =IF(D40=0,0,(E40+F40)/D40) -> 1.2458742 | H40: =(E40+F40)-D40 -> 397234.71 | I40: Revisar compromisso
A41: 3 | B41: =Realizado!D249 -> Monitoração e Contribuição G5 - Skype JB | C41: =Realizado!B249 -> Plat. De Captação E Produção | D41: =IFERROR(VLOOKUP(B41,Orçamento!B:T,19,FALSE),Realizado!E249) -> 259800 | E41: =Realizado!F249+Realizado!G249 -> 12299.99 | F41: =Realizado!I249 -> 486972.08 | G41: =IF(D41=0,0,(E41+F41)/D41) -> 1.9217555 | H41: =(E41+F41)-D41 -> 239472.07 | I41: Revisar compromisso
A42: 4 | B42: =Realizado!D442 -> PAM do Futuro - PoC | C42: =Realizado!B442 -> Plat. De Pós-Prod. E Design | D42: =IFERROR(VLOOKUP(B42,Orçamento!B:T,19,FALSE),Realizado!E442) -> 671563.31 | E42: =Realizado!F442+Realizado!G442 -> 776095.36 | F42: =Realizado!I442 -> 92734.33 | G42: =IF(D42=0,0,(E42+F42)/D42) -> 1.293742 | H42: =(E42+F42)-D42 -> 197266.38 | I42: Revisar compromisso
A43: 5 | B43: =Realizado!D360 -> Operação Remota BSA x JB | C43: =Realizado!B360 -> Plat. De Captação E Produção | D43: =IFERROR(VLOOKUP(B43,Orçamento!B:T,19,FALSE),Realizado!E360) -> 11197.52 | E43: =Realizado!F360+Realizado!G360 -> 138946.57 | F43: =Realizado!I360 -> 10539.51 | G43: =IF(D43=0,0,(E43+F43)/D43) -> 13.349927 | H43: =(E43+F43)-D43 -> 138288.56 | I43: Revisar compromisso
...
